2022-03-29 00:15:15,225 INFO    Thread-3  :16958 [wandb_setup.py:_flush():75] Loading settings from /Users/15leer1/.config/wandb/settings
2022-03-29 00:15:15,225 INFO    Thread-3  :16958 [wandb_setup.py:_flush():75] Loading settings from wandb/settings
2022-03-29 00:15:15,225 INFO    Thread-3  :16958 [wandb_setup.py:_flush():75] Loading settings from environment variables: {'project': 'trash-ai', 'entity': 'trash-ai', 'root_dir': '/Users/15leer1/Documents/GitHub/Garbage-Classification-App', 'sweep_id': 'sckucduo', 'run_id': '8fm5hgd1', 'sweep_param_path': '/Users/15leer1/Documents/GitHub/Garbage-Classification-App/wandb/sweep-sckucduo/config-8fm5hgd1.yaml'}
2022-03-29 00:15:15,225 INFO    Thread-3  :16958 [wandb_setup.py:_flush():75] Inferring run settings from compute environment: {'program_relpath': 'sweeps.py', 'program': '/Users/15leer1/Documents/GitHub/Garbage-Classification-App/sweeps.py'}
2022-03-29 00:15:15,225 INFO    Thread-3  :16958 [wandb_init.py:_log_setup():405] Logging user logs to /Users/15leer1/Documents/GitHub/Garbage-Classification-App/wandb/run-20220329_001515-8fm5hgd1/logs/debug.log
2022-03-29 00:15:15,225 INFO    Thread-3  :16958 [wandb_init.py:_log_setup():406] Logging internal logs to /Users/15leer1/Documents/GitHub/Garbage-Classification-App/wandb/run-20220329_001515-8fm5hgd1/logs/debug-internal.log
2022-03-29 00:15:15,226 INFO    Thread-3  :16958 [wandb_init.py:init():439] calling init triggers
2022-03-29 00:15:15,226 INFO    Thread-3  :16958 [wandb_init.py:init():442] wandb.init called with sweep_config: {'batch_size': 32, 'lr': 0.0031404847440318936, 'model': 'efficientnet_b4'}
config: {}
2022-03-29 00:15:15,226 INFO    Thread-3  :16958 [wandb_init.py:init():492] starting backend
2022-03-29 00:15:15,226 INFO    Thread-3  :16958 [backend.py:_multiprocessing_setup():99] multiprocessing start_methods=spawn,fork,forkserver, using: spawn
2022-03-29 00:15:15,242 INFO    Thread-3  :16958 [backend.py:ensure_launched():219] starting backend process...
2022-03-29 00:15:15,252 INFO    Thread-3  :16958 [backend.py:ensure_launched():224] started backend process with pid: 16969
2022-03-29 00:15:15,254 INFO    Thread-3  :16958 [wandb_init.py:init():501] backend started and connected
2022-03-29 00:15:15,259 INFO    Thread-3  :16958 [wandb_run.py:_config_callback():992] config_cb None None {'batch_size': 32, 'lr': 0.0031404847440318936, 'model': 'efficientnet_b4'}
2022-03-29 00:15:15,261 INFO    Thread-3  :16958 [wandb_init.py:init():565] updated telemetry
2022-03-29 00:15:15,277 INFO    Thread-3  :16958 [wandb_init.py:init():596] communicating run to backend with 30 second timeout
2022-03-29 00:15:15,803 INFO    Thread-3  :16958 [wandb_run.py:_on_init():1759] communicating current version
2022-03-29 00:15:15,921 INFO    Thread-3  :16958 [wandb_run.py:_on_init():1763] got version response 
2022-03-29 00:15:15,921 INFO    Thread-3  :16958 [wandb_init.py:init():625] starting run threads in backend
2022-03-29 00:15:16,030 INFO    Thread-3  :16958 [wandb_run.py:_console_start():1733] atexit reg
2022-03-29 00:15:16,030 INFO    Thread-3  :16958 [wandb_run.py:_redirect():1606] redirect: SettingsConsole.REDIRECT
2022-03-29 00:15:16,031 INFO    Thread-3  :16958 [wandb_run.py:_redirect():1611] Redirecting console.
2022-03-29 00:15:16,031 ERROR   Thread-3  :16958 [wandb_run.py:_redirect():1670] Failed to redirect.
Traceback (most recent call last):
  File "/opt/homebrew/lib/python3.9/site-packages/wandb/sdk/wandb_run.py", line 1663, in _redirect
    out_redir.install()
  File "/opt/homebrew/lib/python3.9/site-packages/wandb/sdk/lib/redirect.py", line 709, in install
    _WSCH.add_fd(self._pipe_read_fd)
  File "/opt/homebrew/lib/python3.9/site-packages/wandb/sdk/lib/redirect.py", line 659, in add_fd
    self._register()
  File "/opt/homebrew/lib/python3.9/site-packages/wandb/sdk/lib/redirect.py", line 644, in _register
    old_handler = signal.signal(signal.SIGWINCH, lambda *_: None)
  File "/opt/homebrew/Cellar/python@3.9/3.9.10/Frameworks/Python.framework/Versions/3.9/lib/python3.9/signal.py", line 56, in signal
    handler = _signal.signal(_enum_to_int(signalnum), _enum_to_int(handler))
ValueError: signal only works in main thread of the main interpreter
2022-03-29 00:15:16,033 INFO    Thread-3  :16958 [wandb_init.py:init():664] run started, returning control to user process
2022-03-29 00:15:18,233 INFO    Thread-3  :16958 [wandb_run.py:finish():1539] finishing run trash-ai/trash-ai/8fm5hgd1
2022-03-29 00:15:18,234 INFO    Thread-3  :16958 [wandb_run.py:_atexit_cleanup():1702] got exitcode: 1
2022-03-29 00:15:18,235 INFO    Thread-3  :16958 [wandb_run.py:_restore():1674] restore
2022-03-29 00:15:18,237 INFO    Thread-3  :16958 [wandb_run.py:_on_finish():1831] got exit ret: file_counts {
  wandb_count: 1
}
pusher_stats {
  uploaded_bytes: 812
  total_bytes: 812
}

2022-03-29 00:15:18,919 INFO    Thread-3  :16958 [wandb_run.py:_on_finish():1831] got exit ret: file_counts {
  wandb_count: 1
}
pusher_stats {
  uploaded_bytes: 812
  total_bytes: 812
}

2022-03-29 00:15:19,066 INFO    Thread-3  :16958 [wandb_run.py:_on_finish():1831] got exit ret: file_counts {
  wandb_count: 1
}
pusher_stats {
  uploaded_bytes: 812
  total_bytes: 812
}

2022-03-29 00:15:19,824 INFO    Thread-3  :16958 [wandb_run.py:_on_finish():1831] got exit ret: file_counts {
  wandb_count: 4
}
pusher_stats {
  uploaded_bytes: 812
  total_bytes: 2609
}

2022-03-29 00:15:19,929 INFO    Thread-3  :16958 [wandb_run.py:_on_finish():1831] got exit ret: file_counts {
  wandb_count: 4
}
pusher_stats {
  uploaded_bytes: 812
  total_bytes: 2609
}

2022-03-29 00:15:20,034 INFO    Thread-3  :16958 [wandb_run.py:_on_finish():1831] got exit ret: file_counts {
  wandb_count: 4
}
pusher_stats {
  uploaded_bytes: 2609
  total_bytes: 2609
}

2022-03-29 00:15:20,144 INFO    Thread-3  :16958 [wandb_run.py:_on_finish():1831] got exit ret: file_counts {
  wandb_count: 4
}
pusher_stats {
  uploaded_bytes: 2609
  total_bytes: 2609
}

2022-03-29 00:15:20,249 INFO    Thread-3  :16958 [wandb_run.py:_on_finish():1831] got exit ret: file_counts {
  wandb_count: 4
}
pusher_stats {
  uploaded_bytes: 2609
  total_bytes: 2609
}

2022-03-29 00:15:20,357 INFO    Thread-3  :16958 [wandb_run.py:_on_finish():1831] got exit ret: file_counts {
  wandb_count: 4
}
pusher_stats {
  uploaded_bytes: 2609
  total_bytes: 2609
}

2022-03-29 00:15:20,462 INFO    Thread-3  :16958 [wandb_run.py:_on_finish():1831] got exit ret: file_counts {
  wandb_count: 4
}
pusher_stats {
  uploaded_bytes: 2609
  total_bytes: 2609
}

2022-03-29 00:15:20,651 INFO    Thread-3  :16958 [wandb_run.py:_on_finish():1831] got exit ret: file_counts {
  wandb_count: 4
}
pusher_stats {
  uploaded_bytes: 2609
  total_bytes: 2609
}

2022-03-29 00:15:20,978 INFO    Thread-3  :16958 [wandb_run.py:_on_finish():1831] got exit ret: done: true
exit_result {
}
file_counts {
  wandb_count: 4
}
pusher_stats {
  uploaded_bytes: 2609
  total_bytes: 2609
}
local_info {
}

2022-03-29 00:15:22,104 INFO    Thread-3  :16958 [wandb_run.py:_footer_history_summary_info():2865] rendering history
2022-03-29 00:15:22,104 INFO    Thread-3  :16958 [wandb_run.py:_footer_history_summary_info():2894] rendering summary
2022-03-29 00:15:22,105 INFO    Thread-3  :16958 [wandb_run.py:_footer_sync_info():2822] logging synced files
