2022-03-29 00:16:42,831 INFO    Thread-29 :16958 [wandb_setup.py:_flush():75] Loading settings from /Users/15leer1/.config/wandb/settings
2022-03-29 00:16:42,831 INFO    Thread-29 :16958 [wandb_setup.py:_flush():75] Loading settings from wandb/settings
2022-03-29 00:16:42,831 INFO    Thread-29 :16958 [wandb_setup.py:_flush():75] Loading settings from environment variables: {'project': 'trash-ai', 'entity': 'trash-ai', 'root_dir': '/Users/15leer1/Documents/GitHub/Garbage-Classification-App', 'run_id': 'i9ev4mgh', 'sweep_param_path': '/Users/15leer1/Documents/GitHub/Garbage-Classification-App/wandb/sweep-sckucduo/config-i9ev4mgh.yaml', 'sweep_id': 'sckucduo'}
2022-03-29 00:16:42,831 INFO    Thread-29 :16958 [wandb_setup.py:_flush():75] Inferring run settings from compute environment: {'program_relpath': 'sweeps.py', 'program': '/Users/15leer1/Documents/GitHub/Garbage-Classification-App/sweeps.py'}
2022-03-29 00:16:42,832 INFO    Thread-29 :16958 [wandb_init.py:_log_setup():405] Logging user logs to /Users/15leer1/Documents/GitHub/Garbage-Classification-App/wandb/run-20220329_001642-i9ev4mgh/logs/debug.log
2022-03-29 00:16:42,832 INFO    Thread-29 :16958 [wandb_init.py:_log_setup():406] Logging internal logs to /Users/15leer1/Documents/GitHub/Garbage-Classification-App/wandb/run-20220329_001642-i9ev4mgh/logs/debug-internal.log
2022-03-29 00:16:42,832 INFO    Thread-29 :16958 [wandb_init.py:init():439] calling init triggers
2022-03-29 00:16:42,832 INFO    Thread-29 :16958 [wandb_init.py:init():442] wandb.init called with sweep_config: {'batch_size': 16, 'lr': 0.000238782015368344, 'model': 'efficientnet_b4'}
config: {}
2022-03-29 00:16:42,832 INFO    Thread-29 :16958 [wandb_init.py:init():492] starting backend
2022-03-29 00:16:42,833 INFO    Thread-29 :16958 [backend.py:_multiprocessing_setup():99] multiprocessing start_methods=spawn,fork,forkserver, using: spawn
2022-03-29 00:16:42,837 INFO    Thread-29 :16958 [backend.py:ensure_launched():219] starting backend process...
2022-03-29 00:16:42,844 INFO    Thread-29 :16958 [backend.py:ensure_launched():224] started backend process with pid: 17026
2022-03-29 00:16:42,846 INFO    Thread-29 :16958 [wandb_init.py:init():501] backend started and connected
2022-03-29 00:16:42,854 INFO    Thread-29 :16958 [wandb_run.py:_config_callback():992] config_cb None None {'batch_size': 16, 'lr': 0.000238782015368344, 'model': 'efficientnet_b4'}
2022-03-29 00:16:42,859 INFO    Thread-29 :16958 [wandb_init.py:init():565] updated telemetry
2022-03-29 00:16:42,874 INFO    Thread-29 :16958 [wandb_init.py:init():596] communicating run to backend with 30 second timeout
2022-03-29 00:16:43,404 INFO    Thread-29 :16958 [wandb_run.py:_on_init():1759] communicating current version
2022-03-29 00:16:43,497 INFO    Thread-29 :16958 [wandb_run.py:_on_init():1763] got version response 
2022-03-29 00:16:43,497 INFO    Thread-29 :16958 [wandb_init.py:init():625] starting run threads in backend
2022-03-29 00:16:43,606 INFO    Thread-29 :16958 [wandb_run.py:_console_start():1733] atexit reg
2022-03-29 00:16:43,607 INFO    Thread-29 :16958 [wandb_run.py:_redirect():1606] redirect: SettingsConsole.REDIRECT
2022-03-29 00:16:43,607 INFO    Thread-29 :16958 [wandb_run.py:_redirect():1611] Redirecting console.
2022-03-29 00:16:43,607 ERROR   Thread-29 :16958 [wandb_run.py:_redirect():1670] Failed to redirect.
Traceback (most recent call last):
  File "/opt/homebrew/lib/python3.9/site-packages/wandb/sdk/wandb_run.py", line 1663, in _redirect
    out_redir.install()
  File "/opt/homebrew/lib/python3.9/site-packages/wandb/sdk/lib/redirect.py", line 709, in install
    _WSCH.add_fd(self._pipe_read_fd)
  File "/opt/homebrew/lib/python3.9/site-packages/wandb/sdk/lib/redirect.py", line 659, in add_fd
    self._register()
  File "/opt/homebrew/lib/python3.9/site-packages/wandb/sdk/lib/redirect.py", line 644, in _register
    old_handler = signal.signal(signal.SIGWINCH, lambda *_: None)
  File "/opt/homebrew/Cellar/python@3.9/3.9.10/Frameworks/Python.framework/Versions/3.9/lib/python3.9/signal.py", line 56, in signal
    handler = _signal.signal(_enum_to_int(signalnum), _enum_to_int(handler))
ValueError: signal only works in main thread of the main interpreter
2022-03-29 00:16:43,608 INFO    Thread-29 :16958 [wandb_init.py:init():664] run started, returning control to user process
2022-03-29 00:16:44,137 INFO    Thread-29 :16958 [wandb_run.py:finish():1539] finishing run trash-ai/trash-ai/i9ev4mgh
2022-03-29 00:16:44,137 INFO    Thread-29 :16958 [wandb_run.py:_atexit_cleanup():1702] got exitcode: 1
2022-03-29 00:16:44,140 INFO    Thread-29 :16958 [wandb_run.py:_restore():1674] restore
2022-03-29 00:16:44,142 INFO    Thread-29 :16958 [wandb_run.py:_on_finish():1831] got exit ret: file_counts {
  wandb_count: 1
}
pusher_stats {
  uploaded_bytes: 812
  total_bytes: 812
}

2022-03-29 00:16:44,814 INFO    Thread-29 :16958 [wandb_run.py:_on_finish():1831] got exit ret: file_counts {
  wandb_count: 1
}
pusher_stats {
  uploaded_bytes: 812
  total_bytes: 812
}

2022-03-29 00:16:44,949 INFO    Thread-29 :16958 [wandb_run.py:_on_finish():1831] got exit ret: file_counts {
  wandb_count: 1
}
pusher_stats {
  uploaded_bytes: 812
  total_bytes: 812
}

2022-03-29 00:16:45,420 INFO    Thread-29 :16958 [wandb_run.py:_on_finish():1831] got exit ret: file_counts {
  wandb_count: 4
}
pusher_stats {
  uploaded_bytes: 812
  total_bytes: 2608
}

2022-03-29 00:16:45,524 INFO    Thread-29 :16958 [wandb_run.py:_on_finish():1831] got exit ret: file_counts {
  wandb_count: 4
}
pusher_stats {
  uploaded_bytes: 812
  total_bytes: 2608
}

2022-03-29 00:16:45,631 INFO    Thread-29 :16958 [wandb_run.py:_on_finish():1831] got exit ret: file_counts {
  wandb_count: 4
}
pusher_stats {
  uploaded_bytes: 2608
  total_bytes: 2608
}

2022-03-29 00:16:45,742 INFO    Thread-29 :16958 [wandb_run.py:_on_finish():1831] got exit ret: file_counts {
  wandb_count: 4
}
pusher_stats {
  uploaded_bytes: 2608
  total_bytes: 2608
}

2022-03-29 00:16:45,847 INFO    Thread-29 :16958 [wandb_run.py:_on_finish():1831] got exit ret: file_counts {
  wandb_count: 4
}
pusher_stats {
  uploaded_bytes: 2608
  total_bytes: 2608
}

2022-03-29 00:16:45,979 INFO    Thread-29 :16958 [wandb_run.py:_on_finish():1831] got exit ret: file_counts {
  wandb_count: 4
}
pusher_stats {
  uploaded_bytes: 2608
  total_bytes: 2608
}

2022-03-29 00:16:46,140 INFO    Thread-29 :16958 [wandb_run.py:_on_finish():1831] got exit ret: file_counts {
  wandb_count: 4
}
pusher_stats {
  uploaded_bytes: 2608
  total_bytes: 2608
}

2022-03-29 00:16:46,495 INFO    Thread-29 :16958 [wandb_run.py:_on_finish():1831] got exit ret: done: true
exit_result {
}
file_counts {
  wandb_count: 4
}
pusher_stats {
  uploaded_bytes: 2608
  total_bytes: 2608
}
local_info {
}

2022-03-29 00:16:47,602 INFO    Thread-29 :16958 [wandb_run.py:_footer_history_summary_info():2865] rendering history
2022-03-29 00:16:47,602 INFO    Thread-29 :16958 [wandb_run.py:_footer_history_summary_info():2894] rendering summary
2022-03-29 00:16:47,603 INFO    Thread-29 :16958 [wandb_run.py:_footer_sync_info():2822] logging synced files
